<?xml version="1.0" encoding="utf-8"?>
<robot
  name="indoor_del_bot">

  <!-- base_link -->
  <link
    name="base_link">
    <inertial>
      <origin
        xyz="-0.00780661123444948 -7.31508946258119E-05 0.10836966300559"
        rpy="0 0 0" />
      <mass
        value="7.29555428414327" />
      <inertia
        ixx="0.125210411522138"
        ixy="-3.83427255194445E-05"
        ixz="-0.00165613454521059"
        iyy="0.167583029848759"
        iyz="9.35047372303265E-07"
        izz="0.280285157053257" />
    </inertial>
    <visual>
      <origin
        xyz="0 0 0"
        rpy="0 0 0" />
      <geometry>
        <mesh
          filename="package://d_bot_description/meshes/base_link.STL" />
      </geometry>
      <material
        name="">
        <color
          rgba="0.827450980392157 0.83921568627451 0.827450980392157 1" />
      </material>
    </visual>
    <collision>
      <origin
        xyz="0 0 0"
        rpy="0 0 0" />
      <geometry>
        <mesh
          filename="package://d_bot_description/meshes/base_link.STL" />
      </geometry>
    </collision>
  </link>

  <!-- lidar link and joint -->
  <link
    name="lidar_link">
    <inertial>
      <origin
        xyz="0.279194541394812 -1.49381448597552E-05 0.122298548059415"
        rpy="0 0 0" />
      <mass
        value="0.165382751635992" />
      <inertia
        ixx="7.88651836105336E-05"
        ixy="4.84717640920877E-08"
        ixz="2.18479443959794E-06"
        iyy="7.51902914938724E-05"
        iyz="2.88601572510436E-08"
        izz="0.000109946753058708" />
    </inertial>
    <visual>
      <origin
        xyz="-0.279194541394812 1.49381448597552E-05 -0.122298548059415"
        rpy="0 0 0" />
      <geometry>
        <mesh
          filename="package://d_bot_description/meshes/lidar_link.STL" />
      </geometry>
      <material
        name="">
        <color
          rgba="0.752941176470588 0.752941176470588 0.752941176470588 0.4" />
      </material>
    </visual>
    <collision>
      <origin
        xyz="-0.279194541394812 1.49381448597552E-05 -0.122298548059415"
        rpy="0 0 0" />
      <geometry>
        <mesh
          filename="package://d_bot_description/meshes/lidar_link.STL" />
      </geometry>
    </collision>
  </link>
  <joint
    name="lidar_link_joint"
    type="fixed">
    <origin
      xyz="0.279194541394812 -1.49381448597552E-05 0.122298548059415"
      rpy="0 0 0" />
    <parent
      link="base_link" />
    <child
      link="lidar_link" />
    <axis
      xyz="1 0 0" />
  </joint>

  <!-- real_sense_left link and joint -->
  <link
    name="rs_left">
    <inertial>
      <origin
        xyz="0.274555027589029 0.0594512444419123 0.217391938332195"
        rpy="0 0 0" />
      <mass
        value="0.0447521571009435" />
      <inertia
        ixx="2.39114045668301E-05"
        ixy="8.20326286217048E-06"
        ixz="-1.82111380306059E-08"
        iyy="7.31204727336871E-06"
        iyz="1.80836025822923E-08"
        izz="2.73608190095255E-05" />
    </inertial>
    <visual>
      <origin
        xyz="-0.274555027589029 -0.0594512444419123 -0.217391938332195"
        rpy="0 0 0" />
      <geometry>
        <mesh
          filename="package://d_bot_description/meshes/rs_left.STL" />
      </geometry>
      <material
        name="">
        <color
          rgba="0.792156862745098 0.819607843137255 0.933333333333333 1" />
      </material>
    </visual>
    <collision>
      <origin
        xyz="-0.274555027589029 -0.0594512444419123 -0.217391938332195"
        rpy="0 0 0" />
      <geometry>
        <mesh
          filename="package://d_bot_description/meshes/rs_left.STL" />
      </geometry>
    </collision>
  </link>
  <joint
    name="rs_left_joint"
    type="fixed">
    <origin
      xyz="0.274555027589029 0.0594512444419123 0.217391938332195"
      rpy="0 0 0" />
    <parent
      link="base_link" />
    <child
      link="rs_left" />
    <axis
      xyz="0 0 0" />
  </joint>

  <!-- real_sense_right link and joint -->
  <link
    name="rs_right">
    <inertial>
      <origin
        xyz="0.273134158939021 -0.0563363041663852 0.215391956342575"
        rpy="0 0 0" />
      <mass
        value="0.0447522720440084" />
      <inertia
        ixx="2.28893414689802E-05"
        ixy="-9.12224588442263E-06"
        ixz="1.2674636414842E-09"
        iyy="8.33417328604517E-06"
        iyz="2.56207062416853E-08"
        izz="2.73608662757534E-05" />
    </inertial>
    <visual>
      <origin
        xyz="-0.273134158939021 0.0563363041663852 -0.215391956342575"
        rpy="0 0 0" />
      <geometry>
        <mesh
          filename="package://d_bot_description/meshes/rs_right.STL" />
      </geometry>
      <material
        name="">
        <color
          rgba="0.792156862745098 0.819607843137255 0.933333333333333 1" />
      </material>
    </visual>
    <collision>
      <origin
        xyz="-0.273134158939021 0.0563363041663852 -0.215391956342575"
        rpy="0 0 0" />
      <geometry>
        <mesh
          filename="package://d_bot_description/meshes/rs_right.STL" />
      </geometry>
    </collision>
  </link>
  <joint
    name="rs_right_joint"
    type="fixed">
    <origin
      xyz="0.273134158939021 -0.0563363041663852 0.215391956342575"
      rpy="0 0 0" />
    <parent
      link="base_link" />
    <child
      link="rs_right" />
    <axis
      xyz="0 0 0" />
  </joint>

  <!-- caster_front_left link and joint -->
  <link
    name="caster_fl">
    <inertial>
      <origin
        xyz="0.191862541507397 0.197610528427432 0.00130276285386216"
        rpy="0 0 0" />
      <mass
        value="0.0334173711421252" />
      <inertia
        ixx="6.33984500469436E-06"
        ixy="3.76037439293872E-08"
        ixz="-6.40304873706217E-22"
        iyy="1.06390050747607E-05"
        iyz="-2.92534718662965E-22"
        izz="6.33951611873327E-06" />
    </inertial>
    <visual>
      <origin
        xyz="-0.191862541507397 -0.197610528427432 -0.00130276285386216"
        rpy="0 0 0" />
      <geometry>
        <mesh
          filename="package://d_bot_description/meshes/caster_fl.STL" />
      </geometry>
      <material
        name="">
        <color
          rgba="0.792156862745098 0.819607843137255 0.933333333333333 1" />
      </material>
    </visual>
    <collision>
      <origin
        xyz="-0.191862541507397 -0.197610528427432 -0.00130276285386216"
        rpy="0 0 0" />
      <geometry>
        <mesh
          filename="package://d_bot_description/meshes/caster_fl.STL" />
      </geometry>
    </collision>
  </link>
  <joint
    name="caster_fl_joint"
    type="continuous">
    <origin
      xyz="0.191862541507397 0.197610528427432 0.00130276285386216"
      rpy="0 0 0" />
    <parent
      link="base_link" />
    <child
      link="caster_fl" />
    <axis
      xyz="0 1 0" />
  </joint>

  <!-- caster_front_right link and joint -->
  <link
    name="caster_fr">
    <inertial>
      <origin
        xyz="0.191862541507396 -0.197389471572568 0.0013027628538621"
        rpy="0 0 0" />
      <mass
        value="0.0334173711421252" />
      <inertia
        ixx="6.33984500469437E-06"
        ixy="3.76037439293871E-08"
        ixz="-5.7474846017805E-22"
        iyy="1.06390050747608E-05"
        iyz="-2.90217181917764E-22"
        izz="6.33951611873328E-06" />
    </inertial>
    <visual>
      <origin
        xyz="-0.191862541507396 0.197389471572568 -0.0013027628538621"
        rpy="0 0 0" />
      <geometry>
        <mesh
          filename="package://d_bot_description/meshes/caster_fr.STL" />
      </geometry>
      <material
        name="">
        <color
          rgba="0.792156862745098 0.819607843137255 0.933333333333333 1" />
      </material>
    </visual>
    <collision>
      <origin
        xyz="-0.191862541507396 0.197389471572568 -0.0013027628538621"
        rpy="0 0 0" />
      <geometry>
        <mesh
          filename="package://d_bot_description/meshes/caster_fr.STL" />
      </geometry>
    </collision>
  </link>
  <joint
    name="caster_fr_joint"
    type="continuous">
    <origin
      xyz="0.191862541507396 -0.197389471572568 0.0013027628538621"
      rpy="0 0 0" />
    <parent
      link="base_link" />
    <child
      link="caster_fr" />
    <axis
      xyz="0 1 0" />
  </joint>

<!-- caster_rear_right link and joint -->
  <link
    name="caster_rr">
    <inertial>
      <origin
        xyz="-0.228137458492605 -0.197389471572567 0.00130276285386094"
        rpy="0 0 0" />
      <mass
        value="0.0334173711421253" />
      <inertia
        ixx="6.33984500469439E-06"
        ixy="3.76037439293856E-08"
        ixz="-3.93390012977437E-22"
        iyy="1.06390050747608E-05"
        iyz="5.27758670867211E-23"
        izz="6.33951611873329E-06" />
    </inertial>
    <visual>
      <origin
        xyz="0.228137458492605 0.197389471572567 -0.00130276285386094"
        rpy="0 0 0" />
      <geometry>
        <mesh
          filename="package://d_bot_description/meshes/caster_rr.STL" />
      </geometry>
      <material
        name="">
        <color
          rgba="0.792156862745098 0.819607843137255 0.933333333333333 1" />
      </material>
    </visual>
    <collision>
      <origin
        xyz="0.228137458492605 0.197389471572567 -0.00130276285386094"
        rpy="0 0 0" />
      <geometry>
        <mesh
          filename="package://d_bot_description/meshes/caster_rr.STL" />
      </geometry>
    </collision>
  </link>
  <joint
    name="caster_rr_joint"
    type="continuous">
    <origin
      xyz="-0.228137458492605 -0.197389471572567 0.00130276285386094"
      rpy="0 0 0" />
    <parent
      link="base_link" />
    <child
      link="caster_rr" />
    <axis
      xyz="0 1 0" />
  </joint>

  <!-- caster_rear_left link and joint -->
  <link
    name="caster_rl">
    <inertial>
      <origin
        xyz="-0.228137458492603 0.197610528427433 0.00130276285386072"
        rpy="0 0 0" />
      <mass
        value="0.0334173711421252" />
      <inertia
        ixx="6.33984500469436E-06"
        ixy="3.76037439293854E-08"
        ixz="-4.09191144021621E-22"
        iyy="1.06390050747607E-05"
        iyz="3.07538745319858E-22"
        izz="6.33951611873327E-06" />
    </inertial>
    <visual>
      <origin
        xyz="0.228137458492603 -0.197610528427433 -0.00130276285386072"
        rpy="0 0 0" />
      <geometry>
        <mesh
          filename="package://d_bot_description/meshes/caster_rl.STL" />
      </geometry>
      <material
        name="">
        <color
          rgba="0.792156862745098 0.819607843137255 0.933333333333333 1" />
      </material>
    </visual>
    <collision>
      <origin
        xyz="0.228137458492603 -0.197610528427433 -0.00130276285386072"
        rpy="0 0 0" />
      <geometry>
        <mesh
          filename="package://d_bot_description/meshes/caster_rl.STL" />
      </geometry>
    </collision>
  </link>
  <joint
    name="caster_rl_joint"
    type="continuous">
    <origin
      xyz="-0.228137458492603 0.197610528427433 0.00130276285386072"
      rpy="0 0 0" />
    <parent
      link="base_link" />
    <child
      link="caster_rl" />
    <axis
      xyz="0 1 0" />
  </joint>

  <!-- drive_wheel_left_link and joint -->
  <link
    name="drive_wheel_left">
    <inertial>
      <origin
        xyz="-7.34417430403589E-06 0.204110516837841 0.0500007440772356"
        rpy="0 0 0" />
      <mass
        value="0.989823090734287" />
      <inertia
        ixx="0.00167927609411678"
        ixy="-3.96993088092875E-07"
        ixz="1.37275681706091E-08"
        iyy="0.00288690083815091"
        iyz="4.02214745015368E-08"
        izz="0.00167922468849555" />
    </inertial>
    <visual>
      <origin
        xyz="7.34417430403589E-06 -0.204110516837841 -0.0500007440772356"
        rpy="0 0 0" />
      <geometry>
        <mesh
          filename="package://d_bot_description/meshes/drive_wheel_left.STL" />
      </geometry>
      <material
        name="">
        <color
          rgba="0.2 0.2 0.2 1" />
      </material>
    </visual>
    <collision>
      <origin
        xyz="7.34417430403589E-06 -0.204110516837841 -0.0500007440772356"
        rpy="0 0 0" />
      <geometry>
        <mesh
          filename="package://d_bot_description/meshes/drive_wheel_left.STL" />
      </geometry>
    </collision>
  </link>
  <!-- xyz="-7.34417430403589E-06 0.204110516837841 0.0500007440772356" -->
  <joint
    name="drive_wheel_left_joint"
    type="continuous">
    <origin
      xyz="-7.34417430403589E-06 0.204110516837841 0.0600007440772356"
      rpy="0 0 0" />
    <parent
      link="base_link" />
    <child
      link="drive_wheel_left" />
    <axis
      xyz="0 1 0" />
  </joint>

  <!-- drive_wheel_right_link and joint -->
  <link
    name="drive_wheel_right">
    <inertial>
      <origin
        xyz="7.34417430392487E-06 -0.204110516837841 0.0500007440772355"
        rpy="0 0 0" />
      <mass
        value="0.989823090734286" />
      <inertia
        ixx="0.00167927609411676"
        ixy="-3.96993088093067E-07"
        ixz="-1.3727568175685E-08"
        iyy="0.00288690083815089"
        iyz="-4.02214744999068E-08"
        izz="0.00167922468849555" />
    </inertial>
    <visual>
      <origin
        xyz="-7.34417430392487E-06 0.204110516837841 -0.0500007440772355"
        rpy="0 0 0" />
      <geometry>
        <mesh
          filename="package://d_bot_description/meshes/drive_wheel_right.STL" />
      </geometry>
      <material
        name="">
        <color
          rgba="0.2 0.2 0.2 1" />
      </material>
    </visual>
    <collision>
      <origin
        xyz="-7.34417430392487E-06 0.204110516837841 -0.0500007440772355"
        rpy="0 0 0" />
      <geometry>
        <mesh
          filename="package://d_bot_description/meshes/drive_wheel_right.STL" />
      </geometry>
    </collision>
  </link>
  <joint
    name="drive_wheel_right_joint"
    type="continuous">
    <origin
      xyz="7.34417430392487E-06 -0.204110516837841 0.0600007440772355"
      rpy="0 0 0" />
    <parent
      link="base_link" />
    <child
      link="drive_wheel_right" />
    <axis
      xyz="0 1 0" />
  </joint>

  <!-- for left drive wheel -->

  <!-- This block provides the simulator (Gazebo) with information on a few additional
  physical properties. See http://gazebosim.org/tutorials/?tut=ros_urdf for more-->
  <gazebo reference="drive_wheel_left">
      <mu1 value="200.0"/>
      <mu2 value="100.0"/>
      <kp value="10000000.0" />
      <kd value="1.0" />
      <material>Gazebo/Grey</material>
  </gazebo>

  <!-- This block connects the wheel joint to an actuator (motor), which informs both
  simulation and visualization of the robot -->
  <transmission name="drive_wheel_left_trans">
      <type>transmission_interface/SimpleTransmission</type>
      <actuator name="drive_wheel_left_motor">
          <mechanicalReduction>1</mechanicalReduction>
      </actuator>
      <joint name="drive_wheel_left_joint">
          <hardwareInterface>hardware_interface/VelocityJointInterface</hardwareInterface>
      </joint>
  </transmission>

  <!-- for right drive wheel -->

  <!-- This block provides the simulator (Gazebo) with information on a few additional
  physical properties. See http://gazebosim.org/tutorials/?tut=ros_urdf for more-->
  <gazebo reference="drive_wheel_right">
      <mu1 value="200.0"/>
      <mu2 value="100.0"/>
      <kp value="10000000.0" />
      <kd value="1.0" />
      <material>Gazebo/Grey</material>
  </gazebo>

  <!-- This block connects the wheel joint to an actuator (motor), which informs both
  simulation and visualization of the robot -->
  <transmission name="drive_wheel_right_trans">
      <type>transmission_interface/SimpleTransmission</type>
      <actuator name="drive_wheel_right_motor">
          <mechanicalReduction>1</mechanicalReduction>
      </actuator>
      <joint name="drive_wheel_right_joint">
          <hardwareInterface>hardware_interface/VelocityJointInterface</hardwareInterface>
      </joint>
  </transmission>




  <!-- Gazebo plugin for ROS Control -->
  <gazebo>

      <plugin name="gazebo_ros_control" filename="libgazebo_ros_control.so">
          <robotNamespace>/</robotNamespace>
      </plugin>

  </gazebo>

</robot>